<?xml version="1.0" ?>
<!-- =================================================================================== -->
<!-- |    This document was autogenerated by xacro from yumi.urdf.xacro                | -->
<!-- |    EDITING THIS FILE BY HAND IS NOT RECOMMENDED                                 | -->
<!-- =================================================================================== -->
<!-- 
  PROGRAMMER: Frederick Wachter
  DATE CREATED: 2016-05-30
  LAST MODIFIED: 2016-05-30
  PURPOSE: Import necessary files to build YuMi URDF with workspace
-->
<robot name="yumi" xmlns:xacro="http://www.ros.org/wiki/xacro">
  <!--                  		   -->
  <!--         IMPORTS         -->
  <!--                  		   -->
  <!-- Import Colors -->
  <material name="Black">
    <color rgba="0.0 0.0 0.0 1.0"/>
  </material>
  <material name="Blue">
    <color rgba="0.0 0.0 0.8 1.0"/>
  </material>
  <material name="Green">
    <color rgba="0.0 0.8 0.0 1.0"/>
  </material>
  <material name="Grey">
    <color rgba="0.5 0.5 0.5 1.0"/>
  </material>
  <material name="Light_Grey">
    <color rgba="0.8 0.8 0.8 1.0"/>
  </material>
  <material name="Ivory">
    <color rgba="1.0 1.0 0.94 1.0"/>
  </material>
  <material name="Orange">
    <color rgba="1.0 0.423529411765 0.0392156862745 1.0"/>
  </material>
  <material name="Brown">
    <color rgba="0.870588235294 0.811764705882 0.764705882353 1.0"/>
  </material>
  <material name="Red">
    <color rgba="0.8 0.0 0.0 1.0"/>
  </material>
  <material name="White">
    <color rgba="1.0 1.0 1.0 1.0"/>
  </material>
  <material name="Drexel_Blue">
    <color rgba="0.027 0.161 0.302 1.0"/>
  </material>
  <material name="SeeThrough">
    <color rgba="0 0 0 0"/>
  </material>
  <material name="Transparent">
    <color rgba="1.0 1.0 1.0 0.5"/>
  </material>
  <!-- Import Constants and Modeling Macros -->
  <!-- Constants -->
  <!-- Model Properties -->
  <!-- Import Workspace -->
  <!-- Import YuMi -->
  <!-- Import Transmissions -->
  <!-- Include Utilities -->
  <!-- Constants -->
  <!-- Model Properties -->
  <!-- Constants -->
  <!-- Import Right Servo Gripper -->
  <!-- Import Transmissions -->
  <!-- Include Utilities -->
  <!-- Constants -->
  <!-- Model Properties -->
  <!-- Constants -->
  <!-- Import Camera Assembly -->
  <!--                  		   -->
  <!--     LINK DEFINITIONS    -->
  <!--                  		   -->
  <!-- World Fixed Link for YuMi -->
  <link name="world"/>
  <!--                  		   -->
  <!--    MACRO DEFINITIONS    -->
  <!--                  		   -->
  <!-- Define Macros for YuMi Import -->
  <!--                         -->
  <!--           BODY          -->
  <!--                         -->
  <joint name="world_joint" type="fixed">
    <origin rpy="0 0 0" xyz="0 0 0.1"/>
    <parent link="world"/>
    <child link="yumi_body"/>
  </joint>
  <link name="yumi_body">
    <inertial>
      <origin rpy="0 0 0" xyz="0 0 0"/>
      <mass value="15"/>
      <inertia ixx="0.5" ixy="0" ixz="0" iyy="0.6" iyz="0" izz="0.3"/>
    </inertial>
    <visual>
      <origin rpy="0 0 0" xyz="0 0 0"/>
      <geometry>
        <mesh filename="package://yumi_description/meshes/body.stl"/>
      </geometry>
      <material name="Light_Grey"/>
    </visual>
    <collision>
      <origin rpy="0 0 0" xyz="0 0 0"/>
      <geometry>
        <mesh filename="package://yumi_description/meshes/coarse/body.stl"/>
      </geometry>
      <material name="Light_Grey"/>
    </collision>
  </link>
  <!--                         -->
  <!--        RIGHT ARM        -->
  <!--                         -->
  <joint name="yumi_joint_1_r" type="revolute">
    <parent link="yumi_body"/>
    <child link="yumi_link_1_r"/>
    <origin rpy="-0.9795   -0.5682   -2.3155" xyz="0.05355 -0.0725 0.41492"/>
    <axis xyz="0 0 1"/>
    <limit effort="300" lower="-2.94087978961" upper="2.94087978961" velocity="3.14159265359"/>
    <dynamics damping="0.5"/>
  </joint>
  <link name="yumi_link_1_r">
    <inertial>
      <origin rpy="0 0 0" xyz="0 -0.03 0.12"/>
      <mass value="2"/>
      <inertia ixx="0.1" ixy="0" ixz="0" iyy="0.1" iyz="0" izz="0.1"/>
    </inertial>
    <visual>
      <origin rpy="0 0 0" xyz="0 0 0"/>
      <geometry>
        <mesh filename="package://yumi_description/meshes/link_1.stl"/>
      </geometry>
      <material name="Grey"/>
    </visual>
    <collision>
      <origin rpy="0 0 0" xyz="0 0 0"/>
      <geometry>
        <mesh filename="package://yumi_description/meshes/coarse/link_1.stl"/>
      </geometry>
      <material name="Grey"/>
    </collision>
  </link>
  <joint name="yumi_joint_2_r" type="revolute">
    <parent link="yumi_link_1_r"/>
    <child link="yumi_link_2_r"/>
    <origin rpy="1.57079632679 0.0 0.0" xyz="0.03 0.0 0.1"/>
    <axis xyz="0 0 1"/>
    <limit effort="300" lower="-2.50454747661" upper="0.759218224618" velocity="3.14159265359"/>
    <dynamics damping="0.5"/>
  </joint>
  <link name="yumi_link_2_r">
    <inertial>
      <origin rpy="0 0 0" xyz="0 0 0"/>
      <mass value="2"/>
      <inertia ixx="0.1" ixy="0" ixz="0" iyy="0.1" iyz="0" izz="0.1"/>
    </inertial>
    <visual>
      <origin rpy="0 0 0" xyz="0 0 0"/>
      <geometry>
        <mesh filename="package://yumi_description/meshes/link_2.stl"/>
      </geometry>
      <material name="Grey"/>
    </visual>
    <collision>
      <origin rpy="0 0 0" xyz="0 0 0"/>
      <geometry>
        <mesh filename="package://yumi_description/meshes/coarse/link_2.stl"/>
      </geometry>
      <material name="Grey"/>
    </collision>
  </link>
  <joint name="yumi_joint_7_r" type="revolute">
    <parent link="yumi_link_2_r"/>
    <child link="yumi_link_3_r"/>
    <origin rpy="-1.57079632679 0.0 0.0" xyz="-0.03 0.17283 0.0"/>
    <axis xyz="0 0 1"/>
    <limit effort="300" lower="-2.94087978961" upper="2.94087978961" velocity="3.14159265359"/>
    <dynamics damping="0.5"/>
  </joint>
  <link name="yumi_link_3_r">
    <inertial>
      <origin rpy="0 0 0" xyz="0 0 0"/>
      <mass value="2"/>
      <inertia ixx="0.1" ixy="0" ixz="0" iyy="0.1" iyz="0" izz="0.1"/>
    </inertial>
    <visual>
      <origin rpy="0 0 0" xyz="0 0 0"/>
      <geometry>
        <mesh filename="package://yumi_description/meshes/link_3.stl"/>
      </geometry>
      <material name="Grey"/>
    </visual>
    <collision>
      <origin rpy="0 0 0" xyz="0 0 0"/>
      <geometry>
        <mesh filename="package://yumi_description/meshes/coarse/link_3.stl"/>
      </geometry>
      <material name="Grey"/>
    </collision>
  </link>
  <joint name="yumi_joint_3_r" type="revolute">
    <parent link="yumi_link_3_r"/>
    <child link="yumi_link_4_r"/>
    <origin rpy="1.57079632679 -1.57079632679 0.0" xyz="-0.04188 0.0 0.07873"/>
    <axis xyz="0 0 1"/>
    <limit effort="300" lower="-2.15548162621" upper="1.3962634016" velocity="3.14159265359"/>
    <dynamics damping="0.5"/>
  </joint>
  <link name="yumi_link_4_r">
    <inertial>
      <origin rpy="0 0 0" xyz="0 0 0"/>
      <mass value="2"/>
      <inertia ixx="0.1" ixy="0" ixz="0" iyy="0.1" iyz="0" izz="0.1"/>
    </inertial>
    <visual>
      <origin rpy="0 0 0" xyz="0 0 0"/>
      <geometry>
        <mesh filename="package://yumi_description/meshes/link_4.stl"/>
      </geometry>
      <material name="Grey"/>
    </visual>
    <collision>
      <origin rpy="0 0 0" xyz="0 0 0"/>
      <geometry>
        <mesh filename="package://yumi_description/meshes/coarse/link_4.stl"/>
      </geometry>
      <material name="Grey"/>
    </collision>
  </link>
  <joint name="yumi_joint_4_r" type="revolute">
    <parent link="yumi_link_4_r"/>
    <child link="yumi_link_5_r"/>
    <origin rpy="-1.57079632679 0.0 0.0" xyz="0.0405 0.16461 0.0"/>
    <axis xyz="0 0 1"/>
    <limit effort="300" lower="-5.06145483078" upper="5.06145483078" velocity="6.98131700798"/>
    <dynamics damping="0.5"/>
  </joint>
  <link name="yumi_link_5_r">
    <inertial>
      <origin rpy="0 0 0" xyz="0 0 0"/>
      <mass value="2"/>
      <inertia ixx="0.1" ixy="0" ixz="0" iyy="0.1" iyz="0" izz="0.1"/>
    </inertial>
    <visual>
      <origin rpy="0 0 0" xyz="0 0 0"/>
      <geometry>
        <mesh filename="package://yumi_description/meshes/link_5.stl"/>
      </geometry>
      <material name="Grey"/>
    </visual>
    <collision>
      <origin rpy="0 0 0" xyz="0 0 0"/>
      <geometry>
        <mesh filename="package://yumi_description/meshes/coarse/link_5.stl"/>
      </geometry>
      <material name="Grey"/>
    </collision>
  </link>
  <joint name="yumi_joint_5_r" type="revolute">
    <parent link="yumi_link_5_r"/>
    <child link="yumi_link_6_r"/>
    <origin rpy="1.57079632679 0.0 0.0" xyz="-0.027 0 0.10039"/>
    <axis xyz="0 0 1"/>
    <limit effort="300" lower="-1.53588974176" upper="2.40855436775" velocity="6.98131700798"/>
    <dynamics damping="0.5"/>
  </joint>
  <link name="yumi_link_6_r">
    <inertial>
      <origin rpy="0 0 0" xyz="0 0 0"/>
      <mass value="2"/>
      <inertia ixx="0.1" ixy="0" ixz="0" iyy="0.1" iyz="0" izz="0.1"/>
    </inertial>
    <visual>
      <origin rpy="0 0 0" xyz="0 0 0"/>
      <geometry>
        <mesh filename="package://yumi_description/meshes/link_6.stl"/>
      </geometry>
      <material name="Grey"/>
    </visual>
    <collision>
      <origin rpy="0 0 0" xyz="0 0 0"/>
      <geometry>
        <mesh filename="package://yumi_description/meshes/coarse/link_6.stl"/>
      </geometry>
      <material name="Grey"/>
    </collision>
  </link>
  <joint name="yumi_joint_6_r" type="revolute">
    <parent link="yumi_link_6_r"/>
    <child link="yumi_link_7_r"/>
    <origin rpy="-1.57079632679 0.0 0.0" xyz="0.027 0.029 0.0"/>
    <axis xyz="0 0 1"/>
    <limit effort="300" lower="-3.99680398707" upper="3.99680398707" velocity="6.98131700798"/>
    <dynamics damping="0.5"/>
  </joint>
  <link name="yumi_link_7_r">
    <inertial>
      <origin rpy="0 0 0" xyz="0 0 0"/>
      <mass value="2"/>
      <inertia ixx="0.1" ixy="0" ixz="0" iyy="0.1" iyz="0" izz="0.1"/>
    </inertial>
    <visual>
      <origin rpy="0 0 0" xyz="0 0 0"/>
      <geometry>
        <mesh filename="package://yumi_description/meshes/link_7.stl"/>
      </geometry>
      <material name="Grey"/>
    </visual>
    <collision>
      <origin rpy="0 0 0" xyz="0 0 0"/>
      <geometry>
        <mesh filename="package://yumi_description/meshes/coarse/link_7.stl"/>
      </geometry>
      <material name="Grey"/>
    </collision>
  </link>
  <!--                         -->
  <!--        LEFT ARM         -->
  <!--                         -->
  <joint name="yumi_joint_1_l" type="revolute">
    <parent link="yumi_body"/>
    <child link="yumi_link_1_l"/>
    <origin rpy="0.9781 -0.5716 2.3180" xyz="0.05355 0.07250 0.41492"/>
    <axis xyz="0 0 1"/>
    <limit effort="300" lower="-2.94087978961" upper="2.94087978961" velocity="3.14159265359"/>
    <dynamics damping="0.5"/>
  </joint>
  <link name="yumi_link_1_l">
    <inertial>
      <origin rpy="0 0 0" xyz="0 -0.03 0.12"/>
      <mass value="2"/>
      <inertia ixx="0.1" ixy="0" ixz="0" iyy="0.1" iyz="0" izz="0.1"/>
    </inertial>
    <visual>
      <origin rpy="0 0 0" xyz="0 0 0"/>
      <geometry>
        <mesh filename="package://yumi_description/meshes/link_1.stl"/>
      </geometry>
      <material name="Grey"/>
    </visual>
    <collision>
      <origin rpy="0 0 0" xyz="0 0 0"/>
      <geometry>
        <mesh filename="package://yumi_description/meshes/coarse/link_1.stl"/>
      </geometry>
      <material name="Grey"/>
    </collision>
  </link>
  <joint name="yumi_joint_2_l" type="revolute">
    <parent link="yumi_link_1_l"/>
    <child link="yumi_link_2_l"/>
    <origin rpy="1.57079632679 0.0 0.0" xyz="0.03 0.0 0.1"/>
    <axis xyz="0 0 1"/>
    <limit effort="300" lower="-2.50454747661" upper="0.759218224618" velocity="3.14159265359"/>
    <dynamics damping="0.5"/>
  </joint>
  <link name="yumi_link_2_l">
    <inertial>
      <origin rpy="0 0 0" xyz="0 0 0"/>
      <mass value="2"/>
      <inertia ixx="0.1" ixy="0" ixz="0" iyy="0.1" iyz="0" izz="0.1"/>
    </inertial>
    <visual>
      <origin rpy="0 0 0" xyz="0 0 0"/>
      <geometry>
        <mesh filename="package://yumi_description/meshes/link_2.stl"/>
      </geometry>
      <material name="Grey"/>
    </visual>
    <collision>
      <origin rpy="0 0 0" xyz="0 0 0"/>
      <geometry>
        <mesh filename="package://yumi_description/meshes/coarse/link_2.stl"/>
      </geometry>
      <material name="Grey"/>
    </collision>
  </link>
  <joint name="yumi_joint_7_l" type="revolute">
    <parent link="yumi_link_2_l"/>
    <child link="yumi_link_3_l"/>
    <origin rpy="-1.57079632679 0.0 0.0" xyz="-0.03 0.17283 0.0"/>
    <axis xyz="0 0 1"/>
    <limit effort="300" lower="-2.94087978961" upper="2.94087978961" velocity="3.14159265359"/>
    <dynamics damping="0.5"/>
  </joint>
  <link name="yumi_link_3_l">
    <inertial>
      <origin rpy="0 0 0" xyz="0 0 0"/>
      <mass value="2"/>
      <inertia ixx="0.1" ixy="0" ixz="0" iyy="0.1" iyz="0" izz="0.1"/>
    </inertial>
    <visual>
      <origin rpy="0 0 0" xyz="0 0 0"/>
      <geometry>
        <mesh filename="package://yumi_description/meshes/link_3.stl"/>
      </geometry>
      <material name="Grey"/>
    </visual>
    <collision>
      <origin rpy="0 0 0" xyz="0 0 0"/>
      <geometry>
        <mesh filename="package://yumi_description/meshes/coarse/link_3.stl"/>
      </geometry>
      <material name="Grey"/>
    </collision>
  </link>
  <joint name="yumi_joint_3_l" type="revolute">
    <parent link="yumi_link_3_l"/>
    <child link="yumi_link_4_l"/>
    <origin rpy="1.57079632679 -1.57079632679 0.0" xyz="-0.04188 0.0 0.07873"/>
    <axis xyz="0 0 1"/>
    <limit effort="300" lower="-2.15548162621" upper="1.3962634016" velocity="3.14159265359"/>
    <dynamics damping="0.5"/>
  </joint>
  <link name="yumi_link_4_l">
    <inertial>
      <origin rpy="0 0 0" xyz="0 0 0"/>
      <mass value="2"/>
      <inertia ixx="0.1" ixy="0" ixz="0" iyy="0.1" iyz="0" izz="0.1"/>
    </inertial>
    <visual>
      <origin rpy="0 0 0" xyz="0 0 0"/>
      <geometry>
        <mesh filename="package://yumi_description/meshes/link_4.stl"/>
      </geometry>
      <material name="Grey"/>
    </visual>
    <collision>
      <origin rpy="0 0 0" xyz="0 0 0"/>
      <geometry>
        <mesh filename="package://yumi_description/meshes/coarse/link_4.stl"/>
      </geometry>
      <material name="Grey"/>
    </collision>
  </link>
  <joint name="yumi_joint_4_l" type="revolute">
    <parent link="yumi_link_4_l"/>
    <child link="yumi_link_5_l"/>
    <origin rpy="-1.57079632679 0.0 0.0" xyz="0.0405 0.16461 0.0"/>
    <axis xyz="0 0 1"/>
    <limit effort="300" lower="-5.06145483078" upper="5.06145483078" velocity="6.98131700798"/>
    <dynamics damping="0.5"/>
  </joint>
  <link name="yumi_link_5_l">
    <inertial>
      <origin rpy="0 0 0" xyz="0 0 0"/>
      <mass value="2"/>
      <inertia ixx="0.1" ixy="0" ixz="0" iyy="0.1" iyz="0" izz="0.1"/>
    </inertial>
    <visual>
      <origin rpy="0 0 0" xyz="0 0 0"/>
      <geometry>
        <mesh filename="package://yumi_description/meshes/link_5.stl"/>
      </geometry>
      <material name="Grey"/>
    </visual>
    <collision>
      <origin rpy="0 0 0" xyz="0 0 0"/>
      <geometry>
        <mesh filename="package://yumi_description/meshes/coarse/link_5.stl"/>
      </geometry>
      <material name="Grey"/>
    </collision>
  </link>
  <joint name="yumi_joint_5_l" type="revolute">
    <parent link="yumi_link_5_l"/>
    <child link="yumi_link_6_l"/>
    <origin rpy="1.57079632679 0.0 0.0" xyz="-0.027 0 0.10039"/>
    <axis xyz="0 0 1"/>
    <limit effort="300" lower="-1.53588974176" upper="2.40855436775" velocity="6.98131700798"/>
    <dynamics damping="0.5"/>
  </joint>
  <link name="yumi_link_6_l">
    <inertial>
      <origin rpy="0 0 0" xyz="0 0 0"/>
      <mass value="2"/>
      <inertia ixx="0.1" ixy="0" ixz="0" iyy="0.1" iyz="0" izz="0.1"/>
    </inertial>
    <visual>
      <origin rpy="0 0 0" xyz="0 0 0"/>
      <geometry>
        <mesh filename="package://yumi_description/meshes/link_6.stl"/>
      </geometry>
      <material name="Grey"/>
    </visual>
    <collision>
      <origin rpy="0 0 0" xyz="0 0 0"/>
      <geometry>
        <mesh filename="package://yumi_description/meshes/coarse/link_6.stl"/>
      </geometry>
      <material name="Grey"/>
    </collision>
  </link>
  <joint name="yumi_joint_6_l" type="revolute">
    <parent link="yumi_link_6_l"/>
    <child link="yumi_link_7_l"/>
    <origin rpy="-1.57079632679 0.0 0.0" xyz="0.027 0.029 0.0"/>
    <axis xyz="0 0 1"/>
    <limit effort="300" lower="-3.99680398707" upper="3.99680398707" velocity="6.98131700798"/>
    <dynamics damping="0.5"/>
  </joint>
  <link name="yumi_link_7_l">
    <inertial>
      <origin rpy="0 0 0" xyz="0 0 0"/>
      <mass value="2"/>
      <inertia ixx="0.1" ixy="0" ixz="0" iyy="0.1" iyz="0" izz="0.1"/>
    </inertial>
    <visual>
      <origin rpy="0 0 0" xyz="0 0 0"/>
      <geometry>
        <mesh filename="package://yumi_description/meshes/link_7.stl"/>
      </geometry>
      <material name="Grey"/>
    </visual>
    <collision>
      <origin rpy="0 0 0" xyz="0 0 0"/>
      <geometry>
        <mesh filename="package://yumi_description/meshes/coarse/link_7.stl"/>
      </geometry>
      <material name="Grey"/>
    </collision>
  </link>
  <!--                            -->
  <!--   YuMi Body Transmission   -->
  <!--                            -->
  <transmission name="yumi_tran_1_r">
    <type>transmission_interface/SimpleTransmission</type>
    <joint name="yumi_joint_1_r">
      <hardwareInterface>yumi</hardwareInterface>
    </joint>
    <actuator name="yumi_motor_1_r">
      <hardwareInterface>yumi</hardwareInterface>
      <mechanicalReduction>1</mechanicalReduction>
    </actuator>
  </transmission>
  <transmission name="yumi_tran_2_r">
    <type>transmission_interface/SimpleTransmission</type>
    <joint name="yumi_joint_2_r">
      <hardwareInterface>yumi</hardwareInterface>
    </joint>
    <actuator name="yumi_motor_2_r">
      <hardwareInterface>yumi</hardwareInterface>
      <mechanicalReduction>1</mechanicalReduction>
    </actuator>
  </transmission>
  <transmission name="yumi_tran_3_r">
    <type>transmission_interface/SimpleTransmission</type>
    <joint name="yumi_joint_3_r">
      <hardwareInterface>yumi</hardwareInterface>
    </joint>
    <actuator name="yumi_motor_3_r">
      <hardwareInterface>yumi</hardwareInterface>
      <mechanicalReduction>1</mechanicalReduction>
    </actuator>
  </transmission>
  <transmission name="yumi_tran_4_r">
    <type>transmission_interface/SimpleTransmission</type>
    <joint name="yumi_joint_4_r">
      <hardwareInterface>yumi</hardwareInterface>
    </joint>
    <actuator name="yumi_motor_4_r">
      <hardwareInterface>yumi</hardwareInterface>
      <mechanicalReduction>1</mechanicalReduction>
    </actuator>
  </transmission>
  <transmission name="yumi_tran_5_r">
    <type>transmission_interface/SimpleTransmission</type>
    <joint name="yumi_joint_5_r">
      <hardwareInterface>yumi</hardwareInterface>
    </joint>
    <actuator name="yumi_motor_5_r">
      <hardwareInterface>yumi</hardwareInterface>
      <mechanicalReduction>1</mechanicalReduction>
    </actuator>
  </transmission>
  <transmission name="yumi_tran_6_r">
    <type>transmission_interface/SimpleTransmission</type>
    <joint name="yumi_joint_6_r">
      <hardwareInterface>yumi</hardwareInterface>
    </joint>
    <actuator name="yumi_motor_6_r">
      <hardwareInterface>yumi</hardwareInterface>
      <mechanicalReduction>1</mechanicalReduction>
    </actuator>
  </transmission>
  <transmission name="yumi_tran_7_r">
    <type>transmission_interface/SimpleTransmission</type>
    <joint name="yumi_joint_7_r">
      <hardwareInterface>yumi</hardwareInterface>
    </joint>
    <actuator name="yumi_motor_7_r">
      <hardwareInterface>yumi</hardwareInterface>
      <mechanicalReduction>1</mechanicalReduction>
    </actuator>
  </transmission>
  <transmission name="yumi_tran_1_l">
    <type>transmission_interface/SimpleTransmission</type>
    <joint name="yumi_joint_1_l">
      <hardwareInterface>yumi</hardwareInterface>
    </joint>
    <actuator name="yumi_motor_1_l">
      <hardwareInterface>yumi</hardwareInterface>
      <mechanicalReduction>1</mechanicalReduction>
    </actuator>
  </transmission>
  <transmission name="yumi_tran_2_l">
    <type>transmission_interface/SimpleTransmission</type>
    <joint name="yumi_joint_2_l">
      <hardwareInterface>yumi</hardwareInterface>
    </joint>
    <actuator name="yumi_motor_2_l">
      <hardwareInterface>yumi</hardwareInterface>
      <mechanicalReduction>1</mechanicalReduction>
    </actuator>
  </transmission>
  <transmission name="yumi_tran_3_l">
    <type>transmission_interface/SimpleTransmission</type>
    <joint name="yumi_joint_3_l">
      <hardwareInterface>yumi</hardwareInterface>
    </joint>
    <actuator name="yumi_motor_3_l">
      <hardwareInterface>yumi</hardwareInterface>
      <mechanicalReduction>1</mechanicalReduction>
    </actuator>
  </transmission>
  <transmission name="yumi_tran_4_l">
    <type>transmission_interface/SimpleTransmission</type>
    <joint name="yumi_joint_4_l">
      <hardwareInterface>yumi</hardwareInterface>
    </joint>
    <actuator name="yumi_motor_4_l">
      <hardwareInterface>yumi</hardwareInterface>
      <mechanicalReduction>1</mechanicalReduction>
    </actuator>
  </transmission>
  <transmission name="yumi_tran_5_l">
    <type>transmission_interface/SimpleTransmission</type>
    <joint name="yumi_joint_5_l">
      <hardwareInterface>yumi</hardwareInterface>
    </joint>
    <actuator name="yumi_motor_5_l">
      <hardwareInterface>yumi</hardwareInterface>
      <mechanicalReduction>1</mechanicalReduction>
    </actuator>
  </transmission>
  <transmission name="yumi_tran_6_l">
    <type>transmission_interface/SimpleTransmission</type>
    <joint name="yumi_joint_6_l">
      <hardwareInterface>yumi</hardwareInterface>
    </joint>
    <actuator name="yumi_motor_6_l">
      <hardwareInterface>yumi</hardwareInterface>
      <mechanicalReduction>1</mechanicalReduction>
    </actuator>
  </transmission>
  <transmission name="yumi_tran_7_l">
    <type>transmission_interface/SimpleTransmission</type>
    <joint name="yumi_joint_7_l">
      <hardwareInterface>yumi</hardwareInterface>
    </joint>
    <actuator name="yumi_motor_7_l">
      <hardwareInterface>yumi</hardwareInterface>
      <mechanicalReduction>1</mechanicalReduction>
    </actuator>
  </transmission>
  <!-- Define Macros for Workspace Import -->
  <!--                         -->
  <!--          TABLE          -->
  <!--                         -->
  <joint name="world_to_table" type="fixed">
    <parent link="world"/>
    <child link="table"/>
    <origin rpy="0 0 0" xyz="-0.07 0.54 -0.013"/>
  </joint>
  <link name="table"/>
  <joint name="table_top_to_table" type="fixed">
    <parent link="table"/>
    <child link="table_top"/>
    <origin rpy="0 0 0" xyz="0 0 0"/>
  </joint>
  <link name="table_top">
    <visual>
      <geometry>
        <box size="0.8 1.6 0.026"/>
      </geometry>
      <origin rpy="0 0 0" xyz="0 0 0"/>
      <material name="Ivory"/>
    </visual>
    <collision>
      <geometry>
        <box size="0.8 1.6 0.026"/>
      </geometry>
      <origin rpy="0 0 0" xyz="0 0 0"/>
      <material name="Ivory"/>
    </collision>
  </link>
  <!--                         -->
  <!--       YUMI STAND        -->
  <!--                         -->
  <joint name="stand_to_world" type="fixed">
    <parent link="yumi_body"/>
    <child link="stand"/>
    <origin rpy="0 0 0" xyz="0 0 0"/>
  </joint>
  <link name="stand"/>
  <joint name="base_to_stand" type="fixed">
    <parent link="stand"/>
    <child link="stand_base"/>
    <origin rpy="0 0 0" xyz="0 0 0"/>
  </joint>
  <link name="stand_base">
    <visual>
      <origin rpy="0 0 0" xyz="165.03939 -0.25716 0.00014"/>
      <origin rpy="0 0 0" xyz=""/>
      <geometry>
        <mesh filename="package://yumi_description/meshes/base/IRB14000_BaseStand_Fixed.stl"/>
      </geometry>
      <material name="Orange"/>
    </visual>
    <collision>
      <origin rpy="0 0 0" xyz="165.03939 -0.25716 0.00014"/>
      <geometry>
        <mesh filename="package://yumi_description/meshes/base/IRB14000_BaseStand_Fixed.stl"/>
      </geometry>
      <material name="Orange"/>
    </collision>
  </link>
  <!-- Define Macros for Right Servo Gripper Import -->
  <!--                         -->
  <!--      YuMi Gripper       -->
  <!--                         -->
  <joint name="yumi_link_7_r_joint" type="fixed">
    <origin rpy="0 0 3.14159265359" xyz="0 0 0.007"/>
    <parent link="yumi_link_7_r"/>
    <child link="gripper_r_base"/>
  </joint>
  <link name="gripper_r_base">
    <inertial>
      <origin rpy="0 0 0" xyz="0 0 0"/>
      <mass value="0.2"/>
      <inertia ixx="0.0001" ixy="0" ixz="0" iyy="0.0001" iyz="0" izz="0.0001"/>
    </inertial>
    <visual>
      <origin rpy="0 0 0" xyz="0 0 0"/>
      <geometry>
        <mesh filename="package://yumi_description/meshes/gripper/base.stl"/>
      </geometry>
      <material name="Light_Grey"/>
    </visual>
    <collision>
      <origin rpy="0 0 0" xyz="0 0 0"/>
      <geometry>
        <mesh filename="package://yumi_description/meshes/gripper/coarse/base.stl"/>
      </geometry>
      <material name="Light_Grey"/>
    </collision>
  </link>
  <joint name="gripper_r_joint" type="prismatic">
    <parent link="gripper_r_base"/>
    <child link="gripper_r_finger_r"/>
    <origin rpy="0 0 0" xyz="0 -0.0065 0.0837"/>
    <axis xyz="-1 0 0"/>
    <limit effort="300" lower="0" upper="0.025" velocity="0.02"/>
    <dynamics damping="0.5"/>
  </joint>
  <link name="gripper_r_finger_r">
    <inertial>
      <origin rpy="0 0 0" xyz="0 0 0"/>
      <mass value="0.01"/>
      <inertia ixx="0.000001" ixy="0" ixz="0" iyy="0.000001" iyz="0" izz="0.000001"/>
    </inertial>
    <visual>
      <origin rpy="0 0 0" xyz="0 0 0"/>
      <geometry>
        <mesh filename="package://yumi_description/meshes/gripper/finger.stl"/>
      </geometry>
      <material name="Grey"/>
    </visual>
    <collision>
      <origin rpy="0 0 0" xyz="0 0 0"/>
      <geometry>
        <mesh filename="package://yumi_description/meshes/gripper/coarse/finger.stl"/>
      </geometry>
      <material name="Grey"/>
    </collision>
  </link>
  <joint name="gripper_r_joint_m" type="prismatic">
    <parent link="gripper_r_base"/>
    <child link="gripper_r_finger_l"/>
    <origin rpy="0 0 3.14159265359" xyz="0 0.0065 0.0837"/>
    <axis xyz="-1 0 0"/>
    <limit effort="300" lower="0" upper="0.025" velocity="0.02"/>
    <dynamics damping="0.5"/>
    <mimic joint="gripper_r_joint"/>
  </joint>
  <link name="gripper_r_finger_l">
    <inertial>
      <origin rpy="0 0 0" xyz="0 0 0"/>
      <mass value="0.01"/>
      <inertia ixx="0.000001" ixy="0" ixz="0" iyy="0.000001" iyz="0" izz="0.000001"/>
    </inertial>
    <visual>
      <origin rpy="0 0 0" xyz="0 0 0"/>
      <geometry>
        <mesh filename="package://yumi_description/meshes/gripper/finger.stl"/>
      </geometry>
      <material name="Grey"/>
    </visual>
    <collision>
      <origin rpy="0 0 0" xyz="0 0 0"/>
      <geometry>
        <mesh filename="package://yumi_description/meshes/gripper/coarse/finger.stl"/>
      </geometry>
      <material name="Grey"/>
    </collision>
  </link>
  <!--                               -->
  <!--   YuMi Gripper Transmission   -->
  <!--                               -->
  <transmission name="gripper_r_tran_1">
    <type>transmission_interface/SimpleTransmission</type>
    <joint name="gripper_r_joint_1">
      <hardwareInterface>yumi</hardwareInterface>
    </joint>
    <actuator name="gripper_r_motor_1">
      <hardwareInterface>yumi</hardwareInterface>
      <mechanicalReduction>1</mechanicalReduction>
    </actuator>
  </transmission>
  <!-- Define Macros for Camera Assembly Import -->
  <!--                         -->
  <!--     CAMERA ASSEMBLY     -->
  <!--                         -->
  <joint name="yumi_link_7_l_joint" type="fixed">
    <parent link="yumi_link_7_l"/>
    <child link="camera_assembly"/>
    <origin rpy="0 0 0" xyz="0 0 0.007"/>
  </joint>
  <link name="camera_assembly">
    <collision>
      <origin rpy="0 0 0" xyz="0 0.025 0.04"/>
      <geometry>
        <box size="0.16 0.17 0.08"/>
      </geometry>
      <material name="Grey"/>
    </collision>
  </link>
  <joint name="camera_holder_assembly" type="fixed">
    <parent link="camera_assembly"/>
    <child link="camera_holder"/>
    <origin rpy="0 0 0" xyz="0 0 0"/>
  </joint>
  <link name="camera_holder">
    <!--                                 -->
    <!-- Need to add inertial properties -->
    <!--      <inertial></inertial>      -->
    <!--     Note Created: 2015-05-23    -->
    <!--                                 -->
    <visual>
      <origin rpy="0 0 0" xyz="-0.0377 -0.0129 0"/>
      <geometry>
        <mesh filename="package://yumi_description/meshes/camera/Camera_Holder.stl"/>
      </geometry>
      <material name="Drexel_Blue"/>
    </visual>
    <collision>
      <origin rpy="0 0 0" xyz="-0.0377 -0.0129 0"/>
      <geometry>
        <mesh filename="package://yumi_description/meshes/camera/Camera_Holder.stl"/>
      </geometry>
      <material name="Drexel_Blue"/>
    </collision>
  </link>
  <link name="creative_camera">
    <visual>
      <origin rpy="0 0 0" xyz="0 0 0"/>
      <geometry>
        <mesh filename="package://yumi_description/meshes/camera/Camera_F200.stl"/>
      </geometry>
      <material name="Drexel_Blue"/>
    </visual>
    <collision>
      <origin rpy="0 0 0" xyz="0 0 0"/>
      <geometry>
        <mesh filename="package://yumi_description/meshes/camera/Camera_F200.stl"/>
      </geometry>
      <material name="Drexel_Blue"/>
    </collision>
  </link>
  <link name="vi_sensor">
    <visual>
      <origin rpy="0 -1.575 -1.5098" xyz="0 0 0"/>
      <geometry>
        <mesh filename="package://yumi_description/meshes/camera/vi_sensor.stl"/>
      </geometry>
      <material name="Drexel_Blue"/>
    </visual>
    <collision>
      <origin rpy="0 -1.575 -1.508" xyz="0 0 0"/>
      <geometry>
        <mesh filename="package://yumi_description/meshes/camera/vi_sensor.stl"/>
      </geometry>
      <material name="Drexel_Blue"/>
    </collision>
  </link>
  <joint name="creative_to_holder" type="fixed">
    <parent link="camera_holder"/>
    <child link="creative_camera"/>
    <origin rpy="0 0 0" xyz="-0.002 0.0765 0.0335"/>
  </joint>
  <joint name="vi_to_holder" type="fixed">
    <parent link="camera_holder"/>
    <child link="vi_sensor"/>
    <origin rpy="0 0 0" xyz="0 -0.0138 0.028"/>
  </joint>
</robot>
