<sdf version='1.6'>
  <model name='yumi'>
    <link name='yumi_top_camera_base'>
      <pose frame=''>0.883 -0.06 0.877 3.12 0.795 0.005</pose>
      <inertial>
        <pose frame=''>0 0 0 0 -0 0</pose>
        <mass>1e-05</mass>
        <inertia>
          <ixx>1e-06</ixx>
          <ixy>0</ixy>
          <ixz>0</ixz>
          <iyy>1e-06</iyy>
          <iyz>0</iyz>
          <izz>1e-06</izz>
        </inertia>
      </inertial>
      <collision name='yumi_top_camera_base_collision'>
        <pose frame=''>0 0 0 0 -0 0</pose>
        <geometry>
          <box>
            <size>0.1 0.1 0.1</size>
          </box>
        </geometry>
        <surface>
          <contact>
            <ode/>
          </contact>
          <friction>
            <ode/>
          </friction>
        </surface>
      </collision>
      <visual name='yumi_top_camera_base_visual'>
        <pose frame=''>0 0 0 0 -0 0</pose>
        <geometry>
          <box>
            <size>0.1 0.1 0.1</size>
          </box>
        </geometry>
        <material>
          <script>
            <name>Gazebo/red</name>
            <uri>file://media/materials/scripts/gazebo.material</uri>
          </script>
        </material>
      </visual>
      <velocity_decay/>
      <gravity>1</gravity>
      <velocity_decay/>
      <sensor name='camera' type='depth'>
        <always_on>1</always_on>
        <update_rate>30</update_rate>
        <camera name='__default__'>
          <horizontal_fov>1.0472</horizontal_fov>
          <image>
            <format>R8G8B8</format>
            <width>640</width>
            <height>480</height>
          </image>
          <clip>
            <near>0.05</near>
            <far>8</far>
          </clip>
        </camera>
        <plugin name='kinect1_camera_controller' filename='libgazebo_ros_openni_kinect.so'>
          <cameraName>kinect1</cameraName>
          <alwaysOn>true</alwaysOn>
          <updateRate>30.0</updateRate>
          <imageTopicName>rgb/image_raw</imageTopicName>
          <depthImageTopicName>depth/image_raw</depthImageTopicName>
          <pointCloudTopicName>depth/points</pointCloudTopicName>
          <cameraInfoTopicName>rgb/camera_info</cameraInfoTopicName>
          <depthImageCameraInfoTopicName>depth/camera_info</depthImageCameraInfoTopicName>
          <frameName>yumi_top_camera_base</frameName>
          <baseline>0.1</baseline>
          <distortion_k1>0.0</distortion_k1>
          <distortion_k2>0.0</distortion_k2>
          <distortion_k3>0.0</distortion_k3>
          <distortion_t1>0.0</distortion_t1>
          <distortion_t2>0.0</distortion_t2>
          <pointCloudCutoff>0.5</pointCloudCutoff>
          <pointCloudCutoffMax>5.0</pointCloudCutoffMax>
        </plugin>
        <visualize>1</visualize>
      </sensor>
    </link>
    <joint name='camera_joint' type='revolute'>
      <child>yumi_top_camera_base</child>
      <parent>world</parent>
      <axis>
        <limit>
          <lower>0</lower>
          <upper>0</upper>
        </limit>
        <dynamics>
          <damping>0</damping>
          <friction>0</friction>
          <spring_reference>0</spring_reference>
          <spring_stiffness>0</spring_stiffness>
        </dynamics>
        <use_parent_model_frame>1</use_parent_model_frame>
        <xyz>0 0 1</xyz>
      </axis>
    </joint>
    <link name='yumi_body'>
      <pose frame=''>0 0 0.1 0 -0 0</pose>
      <inertial>
        <pose frame=''>0 0 0 0 -0 0</pose>
        <mass>15</mass>
        <inertia>
          <ixx>0.5</ixx>
          <ixy>0</ixy>
          <ixz>0</ixz>
          <iyy>0.6</iyy>
          <iyz>0</iyz>
          <izz>0.3</izz>
        </inertia>
      </inertial>
      <collision name='yumi_body_collision'>
        <pose frame=''>0 0 0 0 -0 0</pose>
        <geometry>
          <mesh>
            <scale>1 1 1</scale>
            <uri>model://yumi_description/meshes/coarse/body.stl</uri>
          </mesh>
        </geometry>
        <surface>
          <contact>
            <ode/>
          </contact>
          <friction>
            <ode>
              <mu>0.2</mu>
              <mu2>0.2</mu2>
            </ode>
          </friction>
        </surface>
      </collision>
      <visual name='yumi_body_visual'>
        <pose frame=''>0 0 0 0 -0 0</pose>
        <geometry>
          <mesh>
            <scale>1 1 1</scale>
            <uri>model://yumi_description/meshes/body.stl</uri>
          </mesh>
        </geometry>
        <material>
          <script>
            <name>Gazebo/Ivory</name>
            <uri>file://media/materials/scripts/gazebo.material</uri>
          </script>
        </material>
      </visual>
      <gravity>1</gravity>
      <velocity_decay/>
    </link>
    <joint name='world_joint' type='revolute'>
      <child>yumi_body</child>
      <parent>world</parent>
      <axis>
        <limit>
          <lower>0</lower>
          <upper>0</upper>
        </limit>
        <dynamics>
          <damping>0</damping>
          <friction>0</friction>
          <spring_reference>0</spring_reference>
          <spring_stiffness>0</spring_stiffness>
        </dynamics>
        <use_parent_model_frame>1</use_parent_model_frame>
        <xyz>0 0 1</xyz>
      </axis>
    </joint>
    <link name='yumi_link_1_l'>
      <pose frame=''>0.05355 0.0725 0.51492 0.9781 -0.5716 2.318</pose>
      <inertial>
        <pose frame=''>0 -0.03 0.12 0 -0 0</pose>
        <mass>2</mass>
        <inertia>
          <ixx>0.1</ixx>
          <ixy>0</ixy>
          <ixz>0</ixz>
          <iyy>0.1</iyy>
          <iyz>0</iyz>
          <izz>0.1</izz>
        </inertia>
      </inertial>
      <collision name='yumi_link_1_l_collision'>
        <pose frame=''>0 0 0 0 -0 0</pose>
        <geometry>
          <mesh>
            <scale>1 1 1</scale>
            <uri>model://yumi_description/meshes/coarse/link_1.stl</uri>
          </mesh>
        </geometry>
      </collision>
      <visual name='yumi_link_1_l_visual'>
        <pose frame=''>0 0 0 0 -0 0</pose>
        <geometry>
          <mesh>
            <scale>1 1 1</scale>
            <uri>model://yumi_description/meshes/link_1.stl</uri>
          </mesh>
        </geometry>
      </visual>
    </link>
    <joint name='yumi_joint_1_l' type='revolute'>
      <child>yumi_link_1_l</child>
      <parent>yumi_body</parent>
      <axis>
        <xyz>0.813834 0.341993 0.469803</xyz>
        <limit>
          <lower>-2.94088</lower>
          <upper>2.94088</upper>
          <effort>300</effort>
          <velocity>3.14159</velocity>
        </limit>
        <dynamics>
          <damping>0.5</damping>
          <friction>0</friction>
          <spring_reference>0</spring_reference>
          <spring_stiffness>0</spring_stiffness>
        </dynamics>
        <use_parent_model_frame>1</use_parent_model_frame>
      </axis>
    </joint>
    <link name='yumi_link_2_l'>
      <pose frame=''>0.117787 0.125209 0.57813 2.5489 -0.5716 2.318</pose>
      <inertial>
        <pose frame=''>0 0 0 0 -0 0</pose>
        <mass>2</mass>
        <inertia>
          <ixx>0.1</ixx>
          <ixy>0</ixy>
          <ixz>0</ixz>
          <iyy>0.1</iyy>
          <iyz>0</iyz>
          <izz>0.1</izz>
        </inertia>
      </inertial>
      <collision name='yumi_link_2_l_collision'>
        <pose frame=''>0 0 0 0 -0 0</pose>
        <geometry>
          <mesh>
            <scale>1 1 1</scale>
            <uri>model://yumi_description/meshes/coarse/link_2.stl</uri>
          </mesh>
        </geometry>
      </collision>
      <visual name='yumi_link_2_l_visual'>
        <pose frame=''>0 0 0 0 -0 0</pose>
        <geometry>
          <mesh>
            <scale>1 1 1</scale>
            <uri>model://yumi_description/meshes/link_2.stl</uri>
          </mesh>
        </geometry>
      </visual>
    </link>
    <joint name='yumi_joint_2_l' type='revolute'>
      <child>yumi_link_2_l</child>
      <parent>yumi_link_1_l</parent>
      <axis>
        <xyz>0.104847 0.708787 -0.697587</xyz>
        <limit>
          <lower>-2.50455</lower>
          <upper>0.759218</upper>
          <effort>300</effort>
          <velocity>3.14159</velocity>
        </limit>
        <dynamics>
          <damping>0.5</damping>
          <friction>0</friction>
          <spring_reference>0</spring_reference>
          <spring_stiffness>0</spring_stiffness>
        </dynamics>
        <use_parent_model_frame>1</use_parent_model_frame>
      </axis>
    </joint>
    <link name='yumi_link_3_l'>
      <pose frame=''>0.275588 0.165806 0.643096 0.9781 -0.5716 2.318</pose>
      <inertial>
        <pose frame=''>0 0 0 0 -0 0</pose>
        <mass>2</mass>
        <inertia>
          <ixx>0.1</ixx>
          <ixy>0</ixy>
          <ixz>0</ixz>
          <iyy>0.1</iyy>
          <iyz>0</iyz>
          <izz>0.1</izz>
        </inertia>
      </inertial>
      <collision name='yumi_link_3_l_collision'>
        <pose frame=''>0 0 0 0 -0 0</pose>
        <geometry>
          <mesh>
            <scale>1 1 1</scale>
            <uri>model://yumi_description/meshes/coarse/link_3.stl</uri>
          </mesh>
        </geometry>
      </collision>
      <visual name='yumi_link_3_l_visual'>
        <pose frame=''>0 0 0 0 -0 0</pose>
        <geometry>
          <mesh>
            <scale>1 1 1</scale>
            <uri>model://yumi_description/meshes/link_3.stl</uri>
          </mesh>
        </geometry>
      </visual>
    </link>
    <joint name='yumi_joint_7_l' type='revolute'>
      <child>yumi_link_3_l</child>
      <parent>yumi_link_2_l</parent>
      <axis>
        <xyz>0.813834 0.341993 0.469803</xyz>
        <limit>
          <lower>-2.94088</lower>
          <upper>2.94088</upper>
          <effort>300</effort>
          <velocity>3.14159</velocity>
        </limit>
        <dynamics>
          <damping>0.5</damping>
          <friction>0</friction>
          <spring_reference>0</spring_reference>
          <spring_stiffness>0</spring_stiffness>
        </dynamics>
        <use_parent_model_frame>1</use_parent_model_frame>
      </axis>
    </joint>
    <link name='yumi_link_4_l'>
      <pose frame=''>0.363599 0.166892 0.657428 -2.48197 -0.489067 0.397819</pose>
      <inertial>
        <pose frame=''>0 0 0 0 -0 0</pose>
        <mass>2</mass>
        <inertia>
          <ixx>0.1</ixx>
          <ixy>0</ixy>
          <ixz>0</ixz>
          <iyy>0.1</iyy>
          <iyz>0</iyz>
          <izz>0.1</izz>
        </inertia>
      </inertial>
      <collision name='yumi_link_4_l_collision'>
        <pose frame=''>0 0 0 0 -0 0</pose>
        <geometry>
          <mesh>
            <scale>1 1 1</scale>
            <uri>model://yumi_description/meshes/coarse/link_4.stl</uri>
          </mesh>
        </geometry>
      </collision>
      <visual name='yumi_link_4_l_visual'>
        <pose frame=''>0 0 0 0 -0 0</pose>
        <geometry>
          <mesh>
            <scale>1 1 1</scale>
            <uri>model://yumi_description/meshes/link_4.stl</uri>
          </mesh>
        </geometry>
      </visual>
    </link>
    <joint name='yumi_joint_3_l' type='revolute'>
      <child>yumi_link_4_l</child>
      <parent>yumi_link_3_l</parent>
      <axis>
        <xyz>0.104847 0.708787 -0.697587</xyz>
        <limit>
          <lower>-2.15548</lower>
          <upper>1.39626</upper>
          <effort>300</effort>
          <velocity>3.14159</velocity>
        </limit>
        <dynamics>
          <damping>0.5</damping>
          <friction>0</friction>
          <spring_reference>0</spring_reference>
          <spring_stiffness>0</spring_stiffness>
        </dynamics>
        <use_parent_model_frame>1</use_parent_model_frame>
      </axis>
    </joint>
    <link name='yumi_link_5_l'>
      <pose frame=''>0.490643 0.079182 0.587404 2.23042 -0.489067 0.397819</pose>
      <inertial>
        <pose frame=''>0 0 0 0 -0 0</pose>
        <mass>2</mass>
        <inertia>
          <ixx>0.1</ixx>
          <ixy>0</ixy>
          <ixz>0</ixz>
          <iyy>0.1</iyy>
          <iyz>0</iyz>
          <izz>0.1</izz>
        </inertia>
      </inertial>
      <collision name='yumi_link_5_l_collision'>
        <pose frame=''>0 0 0 0 -0 0</pose>
        <geometry>
          <mesh>
            <scale>1 1 1</scale>
            <uri>model://yumi_description/meshes/coarse/link_5.stl</uri>
          </mesh>
        </geometry>
      </collision>
      <visual name='yumi_link_5_l_visual'>
        <pose frame=''>0 0 0 0 -0 0</pose>
        <geometry>
          <mesh>
            <scale>1 1 1</scale>
            <uri>model://yumi_description/meshes/link_5.stl</uri>
          </mesh>
        </geometry>
      </visual>
    </link>
    <joint name='yumi_joint_4_l' type='revolute'>
      <child>yumi_link_5_l</child>
      <parent>yumi_link_4_l</parent>
      <axis>
        <xyz>0.57156 -0.616978 -0.540978</xyz>
        <limit>
          <lower>-5.06145</lower>
          <upper>5.06145</upper>
          <effort>300</effort>
          <velocity>6.98132</velocity>
        </limit>
        <dynamics>
          <damping>0.5</damping>
          <friction>0</friction>
          <spring_reference>0</spring_reference>
          <spring_stiffness>0</spring_stiffness>
        </dynamics>
        <use_parent_model_frame>1</use_parent_model_frame>
      </axis>
    </joint>
    <link name='yumi_link_6_l'>
      <pose frame=''>0.526049 0.00801 0.520411 -2.48197 -0.489067 0.397819</pose>
      <inertial>
        <pose frame=''>0 0 0 0 -0 0</pose>
        <mass>2</mass>
        <inertia>
          <ixx>0.1</ixx>
          <ixy>0</ixy>
          <ixz>0</ixz>
          <iyy>0.1</iyy>
          <iyz>0</iyz>
          <izz>0.1</izz>
        </inertia>
      </inertial>
      <collision name='yumi_link_6_l_collision'>
        <pose frame=''>0 0 0 0 -0 0</pose>
        <geometry>
          <mesh>
            <scale>1 1 1</scale>
            <uri>model://yumi_description/meshes/coarse/link_6.stl</uri>
          </mesh>
        </geometry>
      </collision>
      <visual name='yumi_link_6_l_visual'>
        <pose frame=''>0 0 0 0 -0 0</pose>
        <geometry>
          <mesh>
            <scale>1 1 1</scale>
            <uri>model://yumi_description/meshes/link_6.stl</uri>
          </mesh>
        </geometry>
      </visual>
    </link>
    <joint name='yumi_joint_5_l' type='revolute'>
      <child>yumi_link_6_l</child>
      <parent>yumi_link_5_l</parent>
      <axis>
        <xyz>0.104847 0.708787 -0.697587</xyz>
        <limit>
          <lower>-1.53589</lower>
          <upper>2.40855</upper>
          <effort>300</effort>
          <velocity>6.98132</velocity>
        </limit>
        <dynamics>
          <damping>0.5</damping>
          <friction>0</friction>
          <spring_reference>0</spring_reference>
          <spring_stiffness>0</spring_stiffness>
        </dynamics>
        <use_parent_model_frame>1</use_parent_model_frame>
      </axis>
    </joint>
    <link name='yumi_link_7_l'>
      <pose frame=''>0.564597 -0.000649 0.517407 2.23042 -0.489067 0.397819</pose>
      <inertial>
        <pose frame=''>0 0 0.000636 0 -0 0</pose>
        <mass>2.2</mass>
        <inertia>
          <ixx>0.100109</ixx>
          <ixy>0</ixy>
          <ixz>0</ixz>
          <iyy>0.100109</iyy>
          <iyz>0</iyz>
          <izz>0.1001</izz>
        </inertia>
      </inertial>
      <collision name='yumi_link_7_l_collision'>
        <pose frame=''>0 0 0 0 -0 0</pose>
        <geometry>
          <mesh>
            <scale>1 1 1</scale>
            <uri>model://yumi_description/meshes/coarse/link_7.stl</uri>
          </mesh>
        </geometry>
      </collision>
      <collision name='yumi_link_7_l_fixed_joint_lump__gripper_l_base_collision_1'>
        <pose frame=''>0 0 0.007 0 -0 -3.14159</pose>
        <geometry>
          <mesh>
            <scale>1 1 1</scale>
            <uri>model://yumi_description/meshes/gripper/coarse/base.stl</uri>
          </mesh>
        </geometry>
        <surface>
          <contact>
            <ode/>
          </contact>
          <friction>
            <ode>
              <mu>0.2</mu>
              <mu2>0.2</mu2>
            </ode>
          </friction>
        </surface>
      </collision>
      <visual name='yumi_link_7_l_visual'>
        <pose frame=''>0 0 0 0 -0 0</pose>
        <geometry>
          <mesh>
            <scale>1 1 1</scale>
            <uri>model://yumi_description/meshes/link_7.stl</uri>
          </mesh>
        </geometry>
      </visual>
      <visual name='yumi_link_7_l_fixed_joint_lump__gripper_l_base_visual_1'>
        <pose frame=''>0 0 0.007 0 -0 -3.14159</pose>
        <geometry>
          <mesh>
            <scale>1 1 1</scale>
            <uri>model://yumi_description/meshes/gripper/base.stl</uri>
          </mesh>
        </geometry>
        <material>
          <script>
            <name>Gazebo/Light_Grey</name>
            <uri>file://media/materials/scripts/gazebo.material</uri>
          </script>
        </material>
      </visual>
      <gravity>1</gravity>
      <velocity_decay/>
    </link>
    <joint name='yumi_joint_6_l' type='revolute'>
      <child>yumi_link_7_l</child>
      <parent>yumi_link_6_l</parent>
      <axis>
        <xyz>0.57156 -0.616978 -0.540978</xyz>
        <limit>
          <lower>-3.9968</lower>
          <upper>3.9968</upper>
          <effort>300</effort>
          <velocity>6.98132</velocity>
        </limit>
        <dynamics>
          <damping>0.5</damping>
          <friction>0</friction>
          <spring_reference>0</spring_reference>
          <spring_stiffness>0</spring_stiffness>
        </dynamics>
        <use_parent_model_frame>1</use_parent_model_frame>
      </axis>
    </joint>
    <link name='gripper_l_finger_r'>
      <pose frame=''>0.615756 -0.061216 0.472875 -2.23042 0.489067 -2.74377</pose>
      <inertial>
        <pose frame=''>0 0 0 0 -0 0</pose>
        <mass>0.01</mass>
        <inertia>
          <ixx>1e-06</ixx>
          <ixy>0</ixy>
          <ixz>0</ixz>
          <iyy>1e-06</iyy>
          <iyz>0</iyz>
          <izz>1e-06</izz>
        </inertia>
      </inertial>
      <collision name='gripper_l_finger_r_collision'>
        <pose frame=''>0 0 0 0 -0 0</pose>
        <geometry>
          <mesh>
            <scale>1 1 1</scale>
            <uri>model://yumi_description/meshes/gripper/coarse/finger.stl</uri>
          </mesh>
        </geometry>
        <surface>
          <contact>
            <ode/>
          </contact>
          <friction>
            <ode/>
          </friction>
        </surface>
      </collision>
      <visual name='gripper_l_finger_r_visual'>
        <pose frame=''>0 0 0 0 -0 0</pose>
        <geometry>
          <mesh>
            <scale>1 1 1</scale>
            <uri>model://yumi_description/meshes/gripper/finger.stl</uri>
          </mesh>
        </geometry>
        <material>
          <script>
            <name>Gazebo/Orange</name>
            <uri>file://media/materials/scripts/gazebo.material</uri>
          </script>
        </material>
      </visual>
      <gravity>1</gravity>
      <velocity_decay/>
      <sensor name='gripper_l_finger_r_bumper' type='contact'>
        <always_on>1</always_on>
        <update_rate>100</update_rate>
        <contact>
          <collision>gripper_l_finger_r_collision</collision>
          <topic>__default_topic__</topic>
        </contact>
        <plugin name='gripper_l_finger_r_plugin' filename='libgazebo_ros_bumper.so'>
          <always_on>1</always_on>
          <update_rate>100</update_rate>
          <frameName>gripper_l_finger_r</frameName>
          <bumperTopicName>gripper_l/fr/contact</bumperTopicName>
        </plugin>
      </sensor>
    </link>
    <joint name='gripper_l_joint' type='prismatic'>
      <child>gripper_l_finger_r</child>
      <parent>yumi_link_7_l</parent>
      <axis>
        <xyz>0.813834 0.341993 0.469803</xyz>
        <limit>
          <lower>0</lower>
          <upper>0.025</upper>
          <effort>300</effort>
          <velocity>0.02</velocity>
        </limit>
        <dynamics>
          <damping>0.5</damping>
          <friction>0</friction>
          <spring_reference>0</spring_reference>
          <spring_stiffness>0</spring_stiffness>
        </dynamics>
        <use_parent_model_frame>1</use_parent_model_frame>
      </axis>
    </joint>
    <link name='gripper_l_finger_l'>
      <pose frame=''>0.617119 -0.052001 0.463806 2.23042 -0.489067 0.397819</pose>
      <inertial>
        <pose frame=''>0 0 0 0 -0 0</pose>
        <mass>0.01</mass>
        <inertia>
          <ixx>1e-06</ixx>
          <ixy>0</ixy>
          <ixz>0</ixz>
          <iyy>1e-06</iyy>
          <iyz>0</iyz>
          <izz>1e-06</izz>
        </inertia>
      </inertial>
      <collision name='gripper_l_finger_l_collision'>
        <pose frame=''>0 0 0 0 -0 0</pose>
        <geometry>
          <mesh>
            <scale>1 1 1</scale>
            <uri>model://yumi_description/meshes/gripper/coarse/finger.stl</uri>
          </mesh>
        </geometry>
        <surface>
          <contact>
            <ode/>
          </contact>
          <friction>
            <ode/>
          </friction>
        </surface>
      </collision>
      <visual name='gripper_l_finger_l_visual'>
        <pose frame=''>0 0 0 0 -0 0</pose>
        <geometry>
          <mesh>
            <scale>1 1 1</scale>
            <uri>model://yumi_description/meshes/gripper/finger.stl</uri>
          </mesh>
        </geometry>
        <material>
          <script>
            <name>Gazebo/Blue</name>
            <uri>file://media/materials/scripts/gazebo.material</uri>
          </script>
        </material>
      </visual>
      <gravity>1</gravity>
      <velocity_decay/>
      <sensor name='gripper_l_finger_l_bumper' type='contact'>
        <always_on>1</always_on>
        <update_rate>100</update_rate>
        <contact>
          <collision>gripper_l_finger_l_collision</collision>
          <topic>__default_topic__</topic>
        </contact>
        <plugin name='gripper_l_finger_l_plugin' filename='libgazebo_ros_bumper.so'>
          <always_on>true</always_on>
          <update_rate>100</update_rate>
          <frameName>gripper_l_finger_l</frameName>
          <bumperTopicName>gripper_l/fl/contact</bumperTopicName>
        </plugin>
      </sensor>
    </link>
    <joint name='gripper_l_joint_m' type='prismatic'>
      <child>gripper_l_finger_l</child>
      <parent>yumi_link_7_l</parent>
      <axis>
        <xyz>-0.813834 -0.341993 -0.469803</xyz>
        <limit>
          <lower>0</lower>
          <upper>0.025</upper>
          <effort>300</effort>
          <velocity>0.02</velocity>
        </limit>
        <dynamics>
          <damping>0.5</damping>
          <friction>0</friction>
          <spring_reference>0</spring_reference>
          <spring_stiffness>0</spring_stiffness>
        </dynamics>
        <use_parent_model_frame>1</use_parent_model_frame>
      </axis>
    </joint>
    <link name='yumi_link_1_r'>
      <pose frame=''>0.05355 -0.0725 0.51492 -0.9795 -0.5682 -2.3155</pose>
      <inertial>
        <pose frame=''>0 -0.03 0.12 0 -0 0</pose>
        <mass>2</mass>
        <inertia>
          <ixx>0.1</ixx>
          <ixy>0</ixy>
          <ixz>0</ixz>
          <iyy>0.1</iyy>
          <iyz>0</iyz>
          <izz>0.1</izz>
        </inertia>
      </inertial>
      <collision name='yumi_link_1_r_collision'>
        <pose frame=''>0 0 0 0 -0 0</pose>
        <geometry>
          <mesh>
            <scale>1 1 1</scale>
            <uri>model://yumi_description/meshes/coarse/link_1.stl</uri>
          </mesh>
        </geometry>
      </collision>
      <visual name='yumi_link_1_r_visual'>
        <pose frame=''>0 0 0 0 -0 0</pose>
        <geometry>
          <mesh>
            <scale>1 1 1</scale>
            <uri>model://yumi_description/meshes/link_1.stl</uri>
          </mesh>
        </geometry>
      </visual>
    </link>
    <joint name='yumi_joint_1_r' type='revolute'>
      <child>yumi_link_1_r</child>
      <parent>yumi_body</parent>
      <axis>
        <xyz>0.813754 -0.342122 0.469848</xyz>
        <limit>
          <lower>-2.94088</lower>
          <upper>2.94088</upper>
          <effort>300</effort>
          <velocity>3.14159</velocity>
        </limit>
        <dynamics>
          <damping>0.5</damping>
          <friction>0</friction>
          <spring_reference>0</spring_reference>
          <spring_stiffness>0</spring_stiffness>
        </dynamics>
        <use_parent_model_frame>1</use_parent_model_frame>
      </axis>
    </joint>
    <link name='yumi_link_2_r'>
      <pose frame=''>0.117788 -0.125305 0.578048 0.591296 -0.5682 -2.3155</pose>
      <inertial>
        <pose frame=''>0 0 0 0 -0 0</pose>
        <mass>2</mass>
        <inertia>
          <ixx>0.1</ixx>
          <ixy>0</ixy>
          <ixz>0</ixz>
          <iyy>0.1</iyy>
          <iyz>0</iyz>
          <izz>0.1</izz>
        </inertia>
      </inertial>
      <collision name='yumi_link_2_r_collision'>
        <pose frame=''>0 0 0 0 -0 0</pose>
        <geometry>
          <mesh>
            <scale>1 1 1</scale>
            <uri>model://yumi_description/meshes/coarse/link_2.stl</uri>
          </mesh>
        </geometry>
      </collision>
      <visual name='yumi_link_2_r_visual'>
        <pose frame=''>0 0 0 0 -0 0</pose>
        <geometry>
          <mesh>
            <scale>1 1 1</scale>
            <uri>model://yumi_description/meshes/link_2.stl</uri>
          </mesh>
        </geometry>
      </visual>
    </link>
    <joint name='yumi_joint_2_r' type='revolute'>
      <child>yumi_link_2_r</child>
      <parent>yumi_link_1_r</parent>
      <axis>
        <xyz>-0.107089 0.706299 0.699767</xyz>
        <limit>
          <lower>-2.50455</lower>
          <upper>0.759218</upper>
          <effort>300</effort>
          <velocity>3.14159</velocity>
        </limit>
        <dynamics>
          <damping>0.5</damping>
          <friction>0</friction>
          <spring_reference>0</spring_reference>
          <spring_stiffness>0</spring_stiffness>
        </dynamics>
        <use_parent_model_frame>1</use_parent_model_frame>
      </axis>
    </joint>
    <link name='yumi_link_3_r'>
      <pose frame=''>0.275566 -0.165841 0.643109 -0.9795 -0.5682 -2.3155</pose>
      <inertial>
        <pose frame=''>0 0 0 0 -0 0</pose>
        <mass>2</mass>
        <inertia>
          <ixx>0.1</ixx>
          <ixy>0</ixy>
          <ixz>0</ixz>
          <iyy>0.1</iyy>
          <iyz>0</iyz>
          <izz>0.1</izz>
        </inertia>
      </inertial>
      <collision name='yumi_link_3_r_collision'>
        <pose frame=''>0 0 0 0 -0 0</pose>
        <geometry>
          <mesh>
            <scale>1 1 1</scale>
            <uri>model://yumi_description/meshes/coarse/link_3.stl</uri>
          </mesh>
        </geometry>
      </collision>
      <visual name='yumi_link_3_r_visual'>
        <pose frame=''>0 0 0 0 -0 0</pose>
        <geometry>
          <mesh>
            <scale>1 1 1</scale>
            <uri>model://yumi_description/meshes/link_3.stl</uri>
          </mesh>
        </geometry>
      </visual>
    </link>
    <joint name='yumi_joint_7_r' type='revolute'>
      <child>yumi_link_3_r</child>
      <parent>yumi_link_2_r</parent>
      <axis>
        <xyz>0.813754 -0.342122 0.469848</xyz>
        <limit>
          <lower>-2.94088</lower>
          <upper>2.94088</upper>
          <effort>300</effort>
          <velocity>3.14159</velocity>
        </limit>
        <dynamics>
          <damping>0.5</damping>
          <friction>0</friction>
          <spring_reference>0</spring_reference>
          <spring_stiffness>0</spring_stiffness>
        </dynamics>
        <use_parent_model_frame>1</use_parent_model_frame>
      </axis>
    </joint>
    <link name='yumi_link_4_r'>
      <pose frame=''>0.363558 -0.166821 0.657563 -0.655546 -0.489119 -0.397989</pose>
      <inertial>
        <pose frame=''>0 0 0 0 -0 0</pose>
        <mass>2</mass>
        <inertia>
          <ixx>0.1</ixx>
          <ixy>0</ixy>
          <ixz>0</ixz>
          <iyy>0.1</iyy>
          <iyz>0</iyz>
          <izz>0.1</izz>
        </inertia>
      </inertial>
      <collision name='yumi_link_4_r_collision'>
        <pose frame=''>0 0 0 0 -0 0</pose>
        <geometry>
          <mesh>
            <scale>1 1 1</scale>
            <uri>model://yumi_description/meshes/coarse/link_4.stl</uri>
          </mesh>
        </geometry>
      </collision>
      <visual name='yumi_link_4_r_visual'>
        <pose frame=''>0 0 0 0 -0 0</pose>
        <geometry>
          <mesh>
            <scale>1 1 1</scale>
            <uri>model://yumi_description/meshes/link_4.stl</uri>
          </mesh>
        </geometry>
      </visual>
    </link>
    <joint name='yumi_joint_3_r' type='revolute'>
      <child>yumi_link_4_r</child>
      <parent>yumi_link_3_r</parent>
      <axis>
        <xyz>-0.107089 0.706299 0.699767</xyz>
        <limit>
          <lower>-2.15548</lower>
          <upper>1.39626</upper>
          <effort>300</effort>
          <velocity>3.14159</velocity>
        </limit>
        <dynamics>
          <damping>0.5</damping>
          <friction>0</friction>
          <spring_reference>0</spring_reference>
          <spring_stiffness>0</spring_stiffness>
        </dynamics>
        <use_parent_model_frame>1</use_parent_model_frame>
      </axis>
    </joint>
    <link name='yumi_link_5_r'>
      <pose frame=''>0.49055 -0.07866 0.588013 -2.22634 -0.489119 -0.397989</pose>
      <inertial>
        <pose frame=''>0 0 0 0 -0 0</pose>
        <mass>2</mass>
        <inertia>
          <ixx>0.1</ixx>
          <ixy>0</ixy>
          <ixz>0</ixz>
          <iyy>0.1</iyy>
          <iyz>0</iyz>
          <izz>0.1</izz>
        </inertia>
      </inertial>
      <collision name='yumi_link_5_r_collision'>
        <pose frame=''>0 0 0 0 -0 0</pose>
        <geometry>
          <mesh>
            <scale>1 1 1</scale>
            <uri>model://yumi_description/meshes/coarse/link_5.stl</uri>
          </mesh>
        </geometry>
      </collision>
      <visual name='yumi_link_5_r_visual'>
        <pose frame=''>0 0 0 0 -0 0</pose>
        <geometry>
          <mesh>
            <scale>1 1 1</scale>
            <uri>model://yumi_description/meshes/link_5.stl</uri>
          </mesh>
        </geometry>
      </visual>
    </link>
    <joint name='yumi_joint_4_r' type='revolute'>
      <child>yumi_link_5_r</child>
      <parent>yumi_link_4_r</parent>
      <axis>
        <xyz>0.571259 0.619754 -0.538116</xyz>
        <limit>
          <lower>-5.06145</lower>
          <upper>5.06145</upper>
          <effort>300</effort>
          <velocity>6.98132</velocity>
        </limit>
        <dynamics>
          <damping>0.5</damping>
          <friction>0</friction>
          <spring_reference>0</spring_reference>
          <spring_stiffness>0</spring_stiffness>
        </dynamics>
        <use_parent_model_frame>1</use_parent_model_frame>
      </axis>
    </joint>
    <link name='yumi_link_6_r'>
      <pose frame=''>0.525927 -0.007205 0.521306 -0.655546 -0.489119 -0.397989</pose>
      <inertial>
        <pose frame=''>0 0 0 0 -0 0</pose>
        <mass>2</mass>
        <inertia>
          <ixx>0.1</ixx>
          <ixy>0</ixy>
          <ixz>0</ixz>
          <iyy>0.1</iyy>
          <iyz>0</iyz>
          <izz>0.1</izz>
        </inertia>
      </inertial>
      <collision name='yumi_link_6_r_collision'>
        <pose frame=''>0 0 0 0 -0 0</pose>
        <geometry>
          <mesh>
            <scale>1 1 1</scale>
            <uri>model://yumi_description/meshes/coarse/link_6.stl</uri>
          </mesh>
        </geometry>
      </collision>
      <visual name='yumi_link_6_r_visual'>
        <pose frame=''>0 0 0 0 -0 0</pose>
        <geometry>
          <mesh>
            <scale>1 1 1</scale>
            <uri>model://yumi_description/meshes/link_6.stl</uri>
          </mesh>
        </geometry>
      </visual>
    </link>
    <joint name='yumi_joint_5_r' type='revolute'>
      <child>yumi_link_6_r</child>
      <parent>yumi_link_5_r</parent>
      <axis>
        <xyz>-0.107089 0.706299 0.699767</xyz>
        <limit>
          <lower>-1.53589</lower>
          <upper>2.40855</upper>
          <effort>300</effort>
          <velocity>6.98132</velocity>
        </limit>
        <dynamics>
          <damping>0.5</damping>
          <friction>0</friction>
          <spring_reference>0</spring_reference>
          <spring_stiffness>0</spring_stiffness>
        </dynamics>
        <use_parent_model_frame>1</use_parent_model_frame>
      </axis>
    </joint>
    <link name='yumi_link_7_r'>
      <pose frame=''>0.564465 0.00153 0.518386 -2.22634 -0.489119 -0.397989</pose>
      <inertial>
        <pose frame=''>0 0 0.000636 0 -0 0</pose>
        <mass>2.2</mass>
        <inertia>
          <ixx>0.100109</ixx>
          <ixy>0</ixy>
          <ixz>0</ixz>
          <iyy>0.100109</iyy>
          <iyz>0</iyz>
          <izz>0.1001</izz>
        </inertia>
      </inertial>
      <collision name='yumi_link_7_r_collision'>
        <pose frame=''>0 0 0 0 -0 0</pose>
        <geometry>
          <mesh>
            <scale>1 1 1</scale>
            <uri>model://yumi_description/meshes/coarse/link_7.stl</uri>
          </mesh>
        </geometry>
      </collision>
      <collision name='yumi_link_7_r_fixed_joint_lump__gripper_r_base_collision_1'>
        <pose frame=''>0 0 0.007 0 -0 -3.14159</pose>
        <geometry>
          <mesh>
            <scale>1 1 1</scale>
            <uri>model://yumi_description/meshes/gripper/coarse/base.stl</uri>
          </mesh>
        </geometry>
        <surface>
          <contact>
            <ode/>
          </contact>
          <friction>
            <ode>
              <mu>0.2</mu>
              <mu2>0.2</mu2>
            </ode>
          </friction>
        </surface>
      </collision>
      <visual name='yumi_link_7_r_visual'>
        <pose frame=''>0 0 0 0 -0 0</pose>
        <geometry>
          <mesh>
            <scale>1 1 1</scale>
            <uri>model://yumi_description/meshes/link_7.stl</uri>
          </mesh>
        </geometry>
      </visual>
      <visual name='yumi_link_7_r_fixed_joint_lump__gripper_r_base_visual_1'>
        <pose frame=''>0 0 0.007 0 -0 -3.14159</pose>
        <geometry>
          <mesh>
            <scale>1 1 1</scale>
            <uri>model://yumi_description/meshes/gripper/base.stl</uri>
          </mesh>
        </geometry>
        <material>
          <script>
            <name>Gazebo/Light_Grey</name>
            <uri>file://media/materials/scripts/gazebo.material</uri>
          </script>
        </material>
      </visual>
      <gravity>1</gravity>
      <velocity_decay/>
    </link>
    <joint name='yumi_joint_6_r' type='revolute'>
      <child>yumi_link_7_r</child>
      <parent>yumi_link_6_r</parent>
      <axis>
        <xyz>0.571259 0.619754 -0.538116</xyz>
        <limit>
          <lower>-3.9968</lower>
          <upper>3.9968</upper>
          <effort>300</effort>
          <velocity>6.98132</velocity>
        </limit>
        <dynamics>
          <damping>0.5</damping>
          <friction>0</friction>
          <spring_reference>0</spring_reference>
          <spring_stiffness>0</spring_stiffness>
        </dynamics>
        <use_parent_model_frame>1</use_parent_model_frame>
      </axis>
    </joint>
    <link name='gripper_r_finger_r'>
      <pose frame=''>0.616974 0.053151 0.465031 2.22634 0.489119 2.7436</pose>
      <inertial>
        <pose frame=''>0 0 0 0 -0 0</pose>
        <mass>0.01</mass>
        <inertia>
          <ixx>1e-06</ixx>
          <ixy>0</ixy>
          <ixz>0</ixz>
          <iyy>1e-06</iyy>
          <iyz>0</iyz>
          <izz>1e-06</izz>
        </inertia>
      </inertial>
      <collision name='gripper_r_finger_r_collision'>
        <pose frame=''>0 0 0 0 -0 0</pose>
        <geometry>
          <mesh>
            <scale>1 1 1</scale>
            <uri>model://yumi_description/meshes/gripper/coarse/finger.stl</uri>
          </mesh>
        </geometry>
        <surface>
          <contact>
            <ode/>
          </contact>
          <friction>
            <ode/>
          </friction>
        </surface>
      </collision>
      <visual name='gripper_r_finger_r_visual'>
        <pose frame=''>0 0 0 0 -0 0</pose>
        <geometry>
          <mesh>
            <scale>1 1 1</scale>
            <uri>model://yumi_description/meshes/gripper/finger.stl</uri>
          </mesh>
        </geometry>
        <material>
          <script>
            <name>Gazebo/Orange</name>
            <uri>file://media/materials/scripts/gazebo.material</uri>
          </script>
        </material>
      </visual>
      <gravity>1</gravity>
      <velocity_decay/>
      <sensor name='gripper_r_finger_r_bumper' type='contact'>
        <always_on>1</always_on>
        <update_rate>100</update_rate>
        <contact>
          <collision>gripper_r_finger_r_collision</collision>
          <topic>__default_topic__</topic>
        </contact>
        <plugin name='gripper_r_finger_r_plugin' filename='libgazebo_ros_bumper.so'>
          <always_on>1</always_on>
          <update_rate>100</update_rate>
          <frameName>gripper_r_finger_r</frameName>
          <bumperTopicName>gripper_r/fr/contact</bumperTopicName>
        </plugin>
      </sensor>
    </link>
    <joint name='gripper_r_joint' type='prismatic'>
      <child>gripper_r_finger_r</child>
      <parent>yumi_link_7_r</parent>
      <axis>
        <xyz>0.813754 -0.342122 0.469848</xyz>
        <limit>
          <lower>0</lower>
          <upper>0.025</upper>
          <effort>300</effort>
          <velocity>0.02</velocity>
        </limit>
        <dynamics>
          <damping>0.5</damping>
          <friction>0</friction>
          <spring_reference>0</spring_reference>
          <spring_stiffness>0</spring_stiffness>
        </dynamics>
        <use_parent_model_frame>1</use_parent_model_frame>
      </axis>
    </joint>
    <link name='gripper_r_finger_l'>
      <pose frame=''>0.615582 0.062333 0.474128 -2.22634 -0.489119 -0.397989</pose>
      <inertial>
        <pose frame=''>0 0 0 0 -0 0</pose>
        <mass>0.01</mass>
        <inertia>
          <ixx>1e-06</ixx>
          <ixy>0</ixy>
          <ixz>0</ixz>
          <iyy>1e-06</iyy>
          <iyz>0</iyz>
          <izz>1e-06</izz>
        </inertia>
      </inertial>
      <collision name='gripper_r_finger_l_collision'>
        <pose frame=''>0 0 0 0 -0 0</pose>
        <geometry>
          <mesh>
            <scale>1 1 1</scale>
            <uri>model://yumi_description/meshes/gripper/coarse/finger.stl</uri>
          </mesh>
        </geometry>
        <surface>
          <contact>
            <ode/>
          </contact>
          <friction>
            <ode/>
          </friction>
        </surface>
      </collision>
      <visual name='gripper_r_finger_l_visual'>
        <pose frame=''>0 0 0 0 -0 0</pose>
        <geometry>
          <mesh>
            <scale>1 1 1</scale>
            <uri>model://yumi_description/meshes/gripper/finger.stl</uri>
          </mesh>
        </geometry>
        <material>
          <script>
            <name>Gazebo/Blue</name>
            <uri>file://media/materials/scripts/gazebo.material</uri>
          </script>
        </material>
      </visual>
      <gravity>1</gravity>
      <velocity_decay/>
      <sensor name='gripper_r_finger_l_bumper' type='contact'>
        <always_on>1</always_on>
        <update_rate>100</update_rate>
        <contact>
          <collision>gripper_r_finger_l_collision</collision>
          <topic>__default_topic__</topic>
        </contact>
        <plugin name='gripper_r_finger_l_plugin' filename='libgazebo_ros_bumper.so'>
          <always_on>true</always_on>
          <update_rate>100</update_rate>
          <frameName>gripper_r_finger_l</frameName>
          <bumperTopicName>gripper_r/fl/contact</bumperTopicName>
        </plugin>
      </sensor>
    </link>
    <joint name='gripper_r_joint_m' type='prismatic'>
      <child>gripper_r_finger_l</child>
      <parent>yumi_link_7_r</parent>
      <axis>
        <xyz>-0.813754 0.342122 -0.469848</xyz>
        <limit>
          <lower>0</lower>
          <upper>0.025</upper>
          <effort>300</effort>
          <velocity>0.02</velocity>
        </limit>
        <dynamics>
          <damping>0.5</damping>
          <friction>0</friction>
          <spring_reference>0</spring_reference>
          <spring_stiffness>0</spring_stiffness>
        </dynamics>
        <use_parent_model_frame>1</use_parent_model_frame>
      </axis>
    </joint>
    <plugin name='gazebo_ros_controller' filename='libgazebo_ros_control.so'>
      <robotNamespace>/yumi</robotNamespace>
    </plugin>
    <plugin name='mimic_plugin' filename='libgazebo_mimic_plugin.so'>
      <joint>gripper_r_joint</joint>
      <mimicJoint>gripper_r_joint_m</mimicJoint>
      <multiplier>1.0</multiplier>
    </plugin>
    <static>0</static>
    <plugin name='mimic_plugin' filename='libgazebo_mimic_plugin.so'>
      <joint>gripper_l_joint</joint>
      <mimicJoint>gripper_l_joint_m</mimicJoint>
      <multiplier>1.0</multiplier>
    </plugin>
  </model>
</sdf>
